<?xml version="1.0"?>
<robot xmlns:xacro="http://ros.org/wiki/xacro" name="platform">
    <xacro:property name="ball_radius" value="0.015" />
    <xacro:property name="platform_radius" value="0.15" />

    <material name="blue">
        <color rgba="0 0 0.8 1"/>
    </material>

    <link name="motion_platform">
        <visual>
            <geometry>
                <cylinder length="0.005" radius="${platform_radius}"/>
            </geometry>
        </visual>
    </link>

    <link name="ball">
        <visual>
            <origin xyz="0 0 ${ball_radius}"/>
            <geometry>
                <sphere radius="${ball_radius}"/>
            </geometry>
            <material name="blue"/>
        </visual>
    </link>

    <link name="world">
    </link>

    <link name="inter_1">
    </link>

    <link name="inter_2">
    </link>

    <joint name="world_to_platform_x" type="revolute">
        <axis xyz="1 0 0"/>
        <limit effort="1000.0" lower="-2" upper="2" velocity="0.5"/>
        <parent link="world"/>
        <child link="inter_2"/>
        <dynamics damping="0.001"/>
    </joint>

    <joint name="world_to_platform_y" type="revolute">
        <axis xyz="0 1 0"/>
        <limit effort="1000.0" lower="-2" upper="2" velocity="0.5"/>
        <parent link="inter_2"/>
        <child link="motion_platform"/>
        <dynamics damping="0.001"/>
    </joint>

    <joint name="platform_to_ball_x" type="prismatic">
        <limit lower="-${platform_radius}" upper="${platform_radius}" effort="100" velocity="1.0"/>
        <origin xyz="0 0 0" rpy="0 0 0"/>
        <parent link="motion_platform"/>
        <child link="inter_1"/>
    </joint>

    <joint name="platform_to_ball_y" type="prismatic">
        <limit lower="-${platform_radius}" upper="${platform_radius}" effort="100" velocity="1.0"/>
        <origin xyz="0 0 0" rpy="0 0 1.57"/>
        <parent link="inter_1"/>
        <child link="ball"/>
    </joint>
</robot>